<?xml version="1.0"?>
<!-- =================================================================================== -->
<!-- |    This document was autogenerated by xacro from
/tmp/solo/robot_properties_solo/src/robot_properties_solo/resources/xacro/solo12.urdf.xacro | -->
<!-- |    EDITING THIS FILE BY HAND IS NOT RECOMMENDED                                 | -->
<!-- =================================================================================== -->
<robot name="solo"
  xmlns:controller="http://playerstage.sourceforge.net/gazebo/xmlschema/#controller"
  xmlns:interface="http://playerstage.sourceforge.net/gazebo/xmlschema/#interface"
  xmlns:sensor="http://playerstage.sourceforge.net/gazebo/xmlschema/#sensor"
  xmlns:xacro="http://playerstage.sourceforge.net/gazebo/xmlschema/#interface">
  <!-- This file is based on:
  https://github.com/open-dynamic-robot-initiative/open_robot_actuator_hardware/blob/master/mechanics/quadruped_robot_12dof_v1/README.md#quadruped-robot-12dof-v1 -->
  <link name="base_link">
    <!-- BASE LINK INERTIAL -->
    <inertial>
      <origin rpy="0 0 0" xyz="-0.00082966 0.00000105 -0.00060210" />
      <mass value="1.572" /> <!-- <mass value="1.25123725" /> -->
      <!-- The base is extremely symmetrical. -->
      <inertia ixx="0.00266220" ixy="-0.00003684" ixz="-0.00001716" iyy="0.01388510"
        iyz="-0.00000009" izz="0.01605370" />
    </inertial>
    <!-- BASE LINK VISUAL -->
    <visual>
      <origin rpy="0 0 0" xyz="0 0 0" />
      <geometry>
        <mesh filename="meshes/stl/solo12/solo_12_base.stl" />
      </geometry>
      <material name="black">
        <color rgba="0.2 0.2 0.2 1.0" />
      </material>
    </visual>
    <!-- BASE LINK COLLISION -->
    <collision>
      <origin rpy="0 0 0" xyz="0 0 0.03" />
      <!-- <geometry>
        <mesh filename="meshes/stl/solo12/solo_12_base.stl" />
      </geometry> -->
      <geometry>
        <box size="0.5 0.1 0.1" />
      </geometry>
      <material name="grey">
        <color rgba="0.8 0.8 0.8 1.0" />
      </material>
    </collision>
    <!-- Bullet specific paramters -->
    <contact>
      <lateral_friction value="1.0" />
      <restitution value="0.5" />
    </contact>
  </link>
  <!-- END BASE LINK -->
  <joint name="FL_HAA" type="revolute">
    <parent link="base_link" />
    <child link="FL_SHOULDER" />
    <limit effort="3" lower="-10" upper="10" velocity="20" />
    <!-- joints rotates around the x-axis -->
    <axis xyz="1 0 0" />
    <origin rpy="0 0 0" xyz="0.2141 0.08750000000000001 0" />
    <!-- pybullet simulation parameters -->
    <dynamics damping="0.0" friction="0.0" />
  </joint>
  <link name="FL_SHOULDER">
    <!-- HAA VISUAL -->
    <visual>
      <origin rpy="0 0 0" xyz="0.0 0 0" />
      <geometry>
        <mesh filename="meshes/stl/solo12/solo12_hip_fe_fl.stl" />
      </geometry>
      <material name="black">
        <color rgba="0.2 0.2 0.2 1.0" />
      </material>
    </visual>
    <!-- HAA LINK COLLISION -->
    <!-- <collision>
      <origin rpy="0 0 0" xyz="0.0 0 0" />
      <geometry>
        <mesh filename="meshes/stl/solo12/solo12_hip_fe_fl.stl" />
      </geometry>
      <material name="grey">
        <color rgba="0.8 0.8 0.8 1.0" />
      </material>
    </collision> -->
    <inertial>
      <mass value="0.14196048" />
      <!-- HAA body inertia -->
      <origin rpy="0 0 0" xyz="-0.09407251 -0.00438935 0.00001384" />
      <inertia ixx="0.00002802" ixy="0.00003687" ixz="-0.00000009" iyy="0.00038264" iyz="0.00000000"
        izz="0.00038050" />
    </inertial>
  </link>
  <joint name="FL_HFE" type="revolute">
    <parent link="FL_SHOULDER" />
    <child link="FL_UPPER_LEG" />
    <limit effort="3" lower="-10" upper="10" velocity="20" />
    <!-- joints rotates around the y-axis -->
    <axis xyz="0 1 0" />
    <origin rpy="0 0 0" xyz="-0.0195 0.014 0" />
    <!-- pybullet simulation parameters -->
    <dynamics damping="0.0" friction="0.0" />
  </joint>
  <link name="FL_UPPER_LEG">
    <!-- Left upper leg inertia -->
    <inertial>
      <mass value="0.14737324" />
      <origin rpy="0 0 0" xyz="0.00001530 0.01767640 -0.07838230" />
      <inertia ixx="0.00041540" ixy="0.00000000" ixz="0.00000010" iyy="0.00041637" iyz="-0.00004589"
        izz="0.00002982" />
    </inertial>
    <!-- UPPER LEG LINK VISUAL -->
    <visual>
      <origin rpy="0 0 0" xyz="0 0 0" />
      <geometry>
        <mesh filename="meshes/stl/without_foot/solo_upper_leg_left_side.stl" />
      </geometry>
      <material name="red">
        <color rgba="0.5 0.0 0.0 1.0" />
      </material>
    </visual>
    <!-- UPPER LEG LINK COLLISION -->
    <collision>
      <origin rpy="0 0 0" xyz="0 0 -0.08" />
      <!-- <geometry>
        <mesh filename="meshes/stl/without_foot/solo_upper_leg_left_side.stl" />
      </geometry> -->
      <geometry>
        <cylinder length="0.16" radius="0.02" />
      </geometry>
      <material name="grey">
        <color rgba="0.8 0.8 0.8 1.0" />
      </material>
    </collision>
    <!-- Bullet specific paramters -->
    <contact>
      <lateral_friction value="1.0" />
      <restitution value="0.5" />
    </contact>
  </link>
  <!-- END UPPER LEG LINK -->
  <!-- KFE: Joint between the upper leg and the lower leg -->
  <joint name="FL_KFE" type="revolute">
    <parent link="FL_UPPER_LEG" />
    <child link="FL_LOWER_LEG" />
    <limit effort="3" lower="-10" upper="10" velocity="20" />
    <!-- joints rotates around the y-axis -->
    <axis xyz="0 1 0" />
    <origin rpy="0 0 0" xyz="0 0.037450000000000004 -0.16" />
    <!-- pybullet simulation parameters -->
    <dynamics damping="0.0" friction="0.0" />
  </joint>
  <link name="FL_LOWER_LEG">
    <!-- Left lower leg inertia -->
    <inertial>
      <mass value="0.02318294" />
      <origin rpy="0 0 0" xyz="0.00000000 0.00776716 -0.07003876" />
      <inertia ixx="0.00008508" ixy="0.00000000" ixz="0.00000000" iyy="0.00008580" iyz="-0.00000200"
        izz="0.00000139" />
    </inertial>
    <!-- LOWER LEG LINK VISUAL -->
    <visual>
      <origin rpy="0 0 0" xyz="0 0 0" />
      <geometry>
        <mesh filename="meshes/stl/without_foot/solo_lower_leg_v2_left_side.stl" />
      </geometry>
      <material name="black">
        <color rgba="0.2 0.2 0.2 1.0" />
      </material>
    </visual>
    <!-- LOWER LEG LINK COLLISION -->
    <collision>
      <origin rpy="0 0 0" xyz="0 0 -0.08" />
      <geometry>
        <cylinder length="0.10" radius="0.01" />
      </geometry>
      <material name="grey">
        <color rgba="0.8 0.8 0.8 1.0" />
      </material>
    </collision>
    <!-- Bullet specific paramters -->
    <contact>
      <lateral_friction value="1.0" />
      <restitution value="0.5" />
    </contact>
  </link>
  <!-- END LOWER LEG LINK -->
  <!-- Joint between the lower leg and the ankle,
         this is only a dummy joint such that we
         can assign coordinate frames to foot-->
  <joint name="FL_ANKLE" type="fixed" dont_collapse="true">
    <parent link="FL_LOWER_LEG" />
    <child link="FL_FOOT" />
    <origin rpy="0 0 0" xyz="0 0.009000000000000001 -0.16" />
    <!-- Limits -->
    <limit effort="3" lower="-10" upper="10" velocity="20" />
    <!-- pybullet simulation parameters -->
    <dynamics damping="0.0" friction="0.0" />
  </joint>
  <link name="FL_FOOT">
    <!-- FOOT INERTIAL -->
    <inertial>
      <origin rpy="0 0 0" xyz="0 0 0.00035767" />
      <mass value="0.00693606" />
      <inertia ixx="0.00000057" ixy="0.0" ixz="0.0" iyy="0.00000084" iyz="0.0" izz="0.00000053" />
    </inertial>
    <!-- FOOT LINK COLLISION -->
    <collision>
      <origin rpy="0 0 0" xyz="0 0 0" />
      <geometry>
        <sphere radius="0.02" />
      </geometry>
      <material name="grey">
        <color rgba="0.8 0.8 0.8 1.0" />
      </material>
    </collision>
    <!-- Bullet specific paramters -->
    <contact>
      <lateral_friction value="1.0" />
      <restitution value="0.5" />
    </contact>
  </link>
  <!-- END FOOT LINK -->
  <joint name="FR_HAA" type="revolute">
    <parent link="base_link" />
    <child link="FR_SHOULDER" />
    <limit effort="3" lower="-10" upper="10" velocity="20" />
    <!-- joints rotates around the x-axis -->
    <axis xyz="1 0 0" />
    <origin rpy="0 0 0" xyz="0.2141 -0.08750000000000001 0" />
    <!-- pybullet simulation parameters -->
    <dynamics damping="0.0" friction="0.0" />
  </joint>
  <link name="FR_SHOULDER">
    <!-- HAA VISUAL -->
    <visual>
      <origin rpy="0 0 0" xyz="0.0 0 0" />
      <geometry>
        <mesh filename="meshes/stl/solo12/solo12_hip_fe_fr.stl" />
      </geometry>
      <material name="black">
        <color rgba="0.2 0.2 0.2 1.0" />
      </material>
    </visual>
    <!-- HAA LINK COLLISION -->
    <!-- <collision>
      <origin rpy="0 0 0" xyz="0.0 0 0" />
      <geometry>
        <mesh filename="meshes/stl/solo12/solo12_hip_fe_fr.stl" />
      </geometry>
      <material name="grey">
        <color rgba="0.8 0.8 0.8 1.0" />
      </material>
    </collision> -->
    <inertial>
      <mass value="0.14196048" />
      <!-- HAA body inertia -->
      <origin rpy="0 0 0" xyz="-0.09407251 0.00438935 -0.00001384" />
      <inertia ixx="0.00002802" ixy="-0.00003687" ixz="0.00000009" iyy="0.00038264" iyz="0.00000000"
        izz="0.00038050" />
    </inertial>
  </link>
  <joint name="FR_HFE" type="revolute">
    <parent link="FR_SHOULDER" />
    <child link="FR_UPPER_LEG" />
    <limit effort="3" lower="-10" upper="10" velocity="20" />
    <!-- joints rotates around the y-axis -->
    <axis xyz="0 1 0" />
    <origin rpy="0 0 0" xyz="-0.0195 -0.014 0" />
    <!-- pybullet simulation parameters -->
    <dynamics damping="0.0" friction="0.0" />
  </joint>
  <link name="FR_UPPER_LEG">
    <!-- Right upper leg inertia -->
    <inertial>
      <mass value="0.14737324" />
      <origin rpy="0 0 0" xyz="-0.00001530 -0.01767640 -0.07838230" />
      <inertia ixx="0.00041540" ixy="0.00000000" ixz="-0.00000010" iyy="0.00041637" iyz="0.00004589"
        izz="0.00002982" />
    </inertial>
    <!-- UPPER LEG LINK VISUAL -->
    <visual>
      <origin rpy="0 0 0" xyz="0 0 0" />
      <geometry>
        <mesh filename="meshes/stl/without_foot/solo_upper_leg_right_side.stl" />
      </geometry>
      <material name="red">
        <color rgba="0.8 0.0 0.0 1.0" />
      </material>
    </visual>
    <!-- UPPER LEG LINK COLLISION -->
    <collision>
      <origin rpy="0 0 0" xyz="0 0 -0.08" />
      <!-- <geometry>
        <mesh filename="meshes/stl/without_foot/solo_upper_leg_right_side.stl" />
      </geometry> -->
      <geometry>
        <cylinder length="0.16" radius="0.02" />
      </geometry>
      <material name="grey">
        <color rgba="0.8 0.8 0.8 1.0" />
      </material>
    </collision>
    <!-- Bullet specific paramters -->
    <contact>
      <lateral_friction value="1.0" />
      <restitution value="0.5" />
    </contact>
  </link>
  <!-- END UPPER LEG LINK -->
  <!-- KFE: Joint between the upper leg and the lower leg -->
  <joint name="FR_KFE" type="revolute">
    <parent link="FR_UPPER_LEG" />
    <child link="FR_LOWER_LEG" />
    <limit effort="3" lower="-10" upper="10" velocity="20" />
    <!-- joints rotates around the y-axis -->
    <axis xyz="0 1 0" />
    <origin rpy="0 0 0" xyz="0 -0.037450000000000004 -0.16" />
    <!-- pybullet simulation parameters -->
    <dynamics damping="0.0" friction="0.0" />
  </joint>
  <link name="FR_LOWER_LEG">
    <!-- Right lower leg inertia -->
    <inertial>
      <mass value="0.02318294" />
      <origin rpy="0 0 0" xyz="0.00000000 -0.00776716 -0.07003876" />
      <inertia ixx="0.00008508" ixy="0.00000000" ixz="0.00000000" iyy="0.00008580" iyz="0.00000200"
        izz="0.00000139" />
    </inertial>
    <!-- LOWER LEG LINK VISUAL -->
    <visual>
      <origin rpy="0 0 0" xyz="0 0 0" />
      <geometry>
        <mesh filename="meshes/stl/without_foot/solo_lower_leg_v2_right_side.stl" />
      </geometry>
      <material name="black">
        <color rgba="0.2 0.2 0.2 1.0" />
      </material>
    </visual>
    <!-- LOWER LEG LINK COLLISION -->
    <collision>
      <origin rpy="0 0 0" xyz="0 0 -0.08" />
      <geometry>
        <cylinder length="0.10" radius="0.01" />
      </geometry>
      <material name="grey">
        <color rgba="0.8 0.8 0.8 1.0" />
      </material>
    </collision>
    <!-- Bullet specific paramters -->
    <contact>
      <lateral_friction value="1.0" />
      <restitution value="0.5" />
    </contact>
  </link>
  <!-- END LOWER LEG LINK -->
  <!-- Joint between the lower leg and the ankle,
         this is only a dummy joint such that we
         can assign coordinate frames to foot-->
  <joint name="FR_ANKLE" type="fixed" dont_collapse="true">
    <parent link="FR_LOWER_LEG" />
    <child link="FR_FOOT" />
    <origin rpy="0 0 0" xyz="0 -0.009000000000000001 -0.16" />
    <!-- Limits -->
    <limit effort="3" lower="-10" upper="10" velocity="20" />
    <!-- pybullet simulation parameters -->
    <dynamics damping="0.0" friction="0.0" />
  </joint>
  <link name="FR_FOOT">
    <!-- FOOT INERTIAL -->
    <inertial>
      <origin rpy="0 0 0" xyz="0 0 0.00035767" />
      <mass value="0.00693606" />
      <inertia ixx="0.00000057" ixy="0.0" ixz="0.0" iyy="0.00000084" iyz="0.0" izz="0.00000053" />
    </inertial>
    <!-- FOOT LINK COLLISION -->
    <collision>
      <origin rpy="0 0 0" xyz="0 0 0" />
      <geometry>
        <sphere radius="0.02" />
      </geometry>
      <material name="grey">
        <color rgba="0.8 0.8 0.8 1.0" />
      </material>
    </collision>
    <!-- Bullet specific paramters -->
    <contact>
      <lateral_friction value="1.0" />
      <restitution value="0.5" />
    </contact>
  </link>
  <!-- END FOOT LINK -->
  <joint name="HL_HAA" type="revolute">
    <parent link="base_link" />
    <child link="HL_SHOULDER" />
    <limit effort="3" lower="-10" upper="10" velocity="20" />
    <!-- joints rotates around the x-axis -->
    <axis xyz="1 0 0" />
    <origin rpy="0 0 0" xyz="-0.2141 0.08750000000000001 0" />
    <!-- pybullet simulation parameters -->
    <dynamics damping="0.0" friction="0.0" />
  </joint>
  <link name="HL_SHOULDER">
    <!-- HAA VISUAL -->
    <visual>
      <origin rpy="0 0 0" xyz="-0.0 0 0" />
      <geometry>
        <mesh filename="meshes/stl/solo12/solo12_hip_fe_hl.stl" />
      </geometry>
      <material name="black">
        <color rgba="0.2 0.2 0.2 1.0" />
      </material>
    </visual>
    <!-- HAA LINK COLLISION -->
    <!-- <collision>
      <origin rpy="0 0 0" xyz="-0.0 0 0" />
      <geometry>
        <mesh filename="meshes/stl/solo12/solo12_hip_fe_hl.stl" />
      </geometry>
      <material name="grey">
        <color rgba="0.8 0.8 0.8 1.0" />
      </material>
    </collision> -->
    <inertial>
      <mass value="0.14196048" />
      <!-- HAA body inertia -->
      <origin rpy="0 0 0" xyz="0.09407251 -0.00438935 -0.00001384" />
      <inertia ixx="0.00002802" ixy="-0.00003687" ixz="-0.00000009" iyy="0.00038264"
        iyz="0.00000000" izz="0.00038050" />
    </inertial>
  </link>
  <joint name="HL_HFE" type="revolute">
    <parent link="HL_SHOULDER" />
    <child link="HL_UPPER_LEG" />
    <limit effort="3" lower="-10" upper="10" velocity="20" />
    <!-- joints rotates around the y-axis -->
    <axis xyz="0 1 0" />
    <origin rpy="0 0 0" xyz="0.0195 0.014 0" />
    <!-- pybullet simulation parameters -->
    <dynamics damping="0.0" friction="0.0" />
  </joint>
  <link name="HL_UPPER_LEG">
    <!-- Left upper leg inertia -->
    <inertial>
      <mass value="0.14737324" />
      <origin rpy="0 0 0" xyz="0.00001530 0.01767640 -0.07838230" />
      <inertia ixx="0.00041540" ixy="0.00000000" ixz="0.00000010" iyy="0.00041637" iyz="-0.00004589"
        izz="0.00002982" />
    </inertial>
    <!-- UPPER LEG LINK VISUAL -->
    <visual>
      <origin rpy="0 0 0" xyz="0 0 0" />
      <geometry>
        <mesh filename="meshes/stl/without_foot/solo_upper_leg_left_side.stl" />
      </geometry>
      <material name="red">
        <color rgba="0.8 0.0 0.0 1.0" />
      </material>
    </visual>
    <!-- UPPER LEG LINK COLLISION -->
    <collision>
      <origin rpy="0 0 0" xyz="0 0 -0.08" />
      <!-- <geometry>
        <mesh filename="meshes/stl/without_foot/solo_upper_leg_left_side.stl" />
      </geometry> -->
      <geometry>
        <cylinder length="0.16" radius="0.02" />
      </geometry>
      <material name="grey">
        <color rgba="0.8 0.8 0.8 1.0" />
      </material>
    </collision>
    <!-- Bullet specific paramters -->
    <contact>
      <lateral_friction value="1.0" />
      <restitution value="0.5" />
    </contact>
  </link>
  <!-- END UPPER LEG LINK -->
  <!-- KFE: Joint between the upper leg and the lower leg -->
  <joint name="HL_KFE" type="revolute">
    <parent link="HL_UPPER_LEG" />
    <child link="HL_LOWER_LEG" />
    <limit effort="3" lower="-10" upper="10" velocity="20" />
    <!-- joints rotates around the y-axis -->
    <axis xyz="0 1 0" />
    <origin rpy="0 0 0" xyz="0 0.037450000000000004 -0.16" />
    <!-- pybullet simulation parameters -->
    <dynamics damping="0.0" friction="0.0" />
  </joint>
  <link name="HL_LOWER_LEG">
    <!-- Left lower leg inertia -->
    <inertial>
      <mass value="0.02318294" />
      <origin rpy="0 0 0" xyz="0.00000000 0.00776716 -0.07003876" />
      <inertia ixx="0.00008508" ixy="0.00000000" ixz="0.00000000" iyy="0.00008580" iyz="-0.00000200"
        izz="0.00000139" />
    </inertial>
    <!-- LOWER LEG LINK VISUAL -->
    <visual>
      <origin rpy="0 0 0" xyz="0 0 0" />
      <geometry>
        <mesh filename="meshes/stl/without_foot/solo_lower_leg_v2_left_side.stl" />
      </geometry>
      <material name="black">
        <color rgba="0.2 0.2 0.2 1.0" />
      </material>
    </visual>
    <!-- LOWER LEG LINK COLLISION -->
    <collision>
      <origin rpy="0 0 0" xyz="0 0 -0.08" />
      <geometry>
        <cylinder length="0.10" radius="0.01" />
      </geometry>
      <material name="grey">
        <color rgba="0.8 0.8 0.8 1.0" />
      </material>
    </collision>
    <!-- Bullet specific paramters -->
    <contact>
      <lateral_friction value="1.0" />
      <restitution value="0.5" />
    </contact>
  </link>
  <!-- END LOWER LEG LINK -->
  <!-- Joint between the lower leg and the ankle,
         this is only a dummy joint such that we
         can assign coordinate frames to foot-->
  <joint name="HL_ANKLE" type="fixed" dont_collapse="true">
    <parent link="HL_LOWER_LEG" />
    <child link="HL_FOOT" />
    <origin rpy="0 0 0" xyz="0 0.009000000000000001 -0.16" />
    <!-- Limits -->
    <limit effort="3" lower="-10" upper="10" velocity="20" />
    <!-- pybullet simulation parameters -->
    <dynamics damping="0.0" friction="0.0" />
  </joint>
  <link name="HL_FOOT">
    <!-- FOOT INERTIAL -->
    <inertial>
      <origin rpy="0 0 0" xyz="0 0 0.00035767" />
      <mass value="0.00693606" />
      <inertia ixx="0.00000057" ixy="0.0" ixz="0.0" iyy="0.00000084" iyz="0.0" izz="0.00000053" />
    </inertial>
    <!-- FOOT LINK COLLISION -->
    <collision>
      <origin rpy="0 0 0" xyz="0 0 0" />
      <geometry>
        <sphere radius="0.02" />
      </geometry>
      <material name="grey">
        <color rgba="0.8 0.8 0.8 1.0" />
      </material>
    </collision>
    <!-- Bullet specific paramters -->
    <contact>
      <lateral_friction value="1.0" />
      <restitution value="0.5" />
    </contact>
  </link>
  <!-- END FOOT LINK -->
  <joint name="HR_HAA" type="revolute">
    <parent link="base_link" />
    <child link="HR_SHOULDER" />
    <limit effort="3" lower="-10" upper="10" velocity="20" />
    <!-- joints rotates around the x-axis -->
    <axis xyz="1 0 0" />
    <origin rpy="0 0 0" xyz="-0.2141 -0.08750000000000001 0" />
    <!-- pybullet simulation parameters -->
    <dynamics damping="0.0" friction="0.0" />
  </joint>
  <link name="HR_SHOULDER">
    <!-- HAA VISUAL -->
    <visual>
      <origin rpy="0 0 0" xyz="-0.0 0 0" />
      <geometry>
        <mesh filename="meshes/stl/solo12/solo12_hip_fe_hr.stl" />
      </geometry>
      <material name="black">
        <color rgba="0.2 0.2 0.2 1.0" />
      </material>
    </visual>
    <!-- HAA LINK COLLISION -->
    <!-- <collision>
      <origin rpy="0 0 0" xyz="-0.0 0 0" />
      <geometry>
        <mesh filename="meshes/stl/solo12/solo12_hip_fe_hr.stl" />
      </geometry>
      <material name="grey">
        <color rgba="0.8 0.8 0.8 1.0" />
      </material>
    </collision> -->
    <inertial>
      <mass value="0.14196048" />
      <!-- HAA body inertia -->
      <origin rpy="0 0 0" xyz="0.09407251 0.00438935 0.00001384" />
      <inertia ixx="0.00002802" ixy="0.00003687" ixz="0.00000009" iyy="0.00038264" iyz="0.00000000"
        izz="0.00038050" />
    </inertial>
  </link>
  <joint name="HR_HFE" type="revolute">
    <parent link="HR_SHOULDER" />
    <child link="HR_UPPER_LEG" />
    <limit effort="3" lower="-10" upper="10" velocity="20" />
    <!-- joints rotates around the y-axis -->
    <axis xyz="0 1 0" />
    <origin rpy="0 0 0" xyz="0.0195 -0.014 0" />
    <!-- pybullet simulation parameters -->
    <dynamics damping="0.0" friction="0.0" />
  </joint>
  <link name="HR_UPPER_LEG">
    <!-- Right upper leg inertia -->
    <inertial>
      <mass value="0.14737324" />
      <origin rpy="0 0 0" xyz="-0.00001530 -0.01767640 -0.07838230" />
      <inertia ixx="0.00041540" ixy="0.00000000" ixz="-0.00000010" iyy="0.00041637" iyz="0.00004589"
        izz="0.00002982" />
    </inertial>
    <!-- UPPER LEG LINK VISUAL -->
    <visual>
      <origin rpy="0 0 0" xyz="0 0 0" />
      <geometry>
        <mesh filename="meshes/stl/without_foot/solo_upper_leg_right_side.stl" />
      </geometry>
      <material name="red">
        <color rgba="0.8 0.0 0.0 1.0" />
      </material>
    </visual>
    <!-- UPPER LEG LINK COLLISION -->
    <collision>
      <origin rpy="0 0 0" xyz="0 0 -0.08" />
      <!-- <geometry>
        <mesh filename="meshes/stl/without_foot/solo_upper_leg_right_side.stl" />
      </geometry> -->
      <geometry>
        <cylinder length="0.16" radius="0.02" />
      </geometry>
      <material name="grey">
        <color rgba="0.8 0.8 0.8 1.0" />
      </material>
    </collision>
    <!-- Bullet specific paramters -->
    <contact>
      <lateral_friction value="1.0" />
      <restitution value="0.5" />
    </contact>
  </link>
  <!-- END UPPER LEG LINK -->
  <!-- KFE: Joint between the upper leg and the lower leg -->
  <joint name="HR_KFE" type="revolute">
    <parent link="HR_UPPER_LEG" />
    <child link="HR_LOWER_LEG" />
    <limit effort="3" lower="-10" upper="10" velocity="20" />
    <!-- joints rotates around the y-axis -->
    <axis xyz="0 1 0" />
    <origin rpy="0 0 0" xyz="0 -0.037450000000000004 -0.16" />
    <!-- pybullet simulation parameters -->
    <dynamics damping="0.0" friction="0.0" />
  </joint>
  <link name="HR_LOWER_LEG">
    <!-- Right lower leg inertia -->
    <inertial>
      <mass value="0.02318294" />
      <origin rpy="0 0 0" xyz="0.00000000 -0.00776716 -0.07003876" />
      <inertia ixx="0.00008508" ixy="0.00000000" ixz="0.00000000" iyy="0.00008580" iyz="0.00000200"
        izz="0.00000139" />
    </inertial>
    <!-- LOWER LEG LINK VISUAL -->
    <visual>
      <origin rpy="0 0 0" xyz="0 0 0" />
      <geometry>
        <mesh filename="meshes/stl/without_foot/solo_lower_leg_v2_right_side.stl" />
      </geometry>
      <material name="black">
        <color rgba="0.2 0.2 0.2 1.0" />
      </material>
    </visual>
    <!-- LOWER LEG LINK COLLISION -->
    <collision>
      <origin rpy="0 0 0" xyz="0 0 -0.08" />
      <geometry>
        <cylinder length="0.10" radius="0.01" />
      </geometry>
      <material name="grey">
        <color rgba="0.8 0.8 0.8 1.0" />
      </material>
    </collision>
    <!-- Bullet specific paramters -->
    <contact>
      <lateral_friction value="1.0" />
      <restitution value="0.5" />
    </contact>
  </link>
  <!-- END LOWER LEG LINK -->
  <!-- Joint between the lower leg and the ankle,
         this is only a dummy joint such that we
         can assign coordinate frames to foot-->
  <joint name="HR_ANKLE" type="fixed" dont_collapse="true">
    <parent link="HR_LOWER_LEG" />
    <child link="HR_FOOT" />
    <origin rpy="0 0 0" xyz="0 -0.009000000000000001 -0.16" />
    <!-- Limits -->
    <limit effort="3" lower="-10" upper="10" velocity="20" />
    <!-- pybullet simulation parameters -->
    <dynamics damping="0.0" friction="0.0" />
  </joint>
  <link name="HR_FOOT">
    <!-- FOOT INERTIAL -->
    <inertial>
      <origin rpy="0 0 0" xyz="0 0 0.00035767" />
      <mass value="0.00693606" />
      <inertia ixx="0.00000057" ixy="0.0" ixz="0.0" iyy="0.00000084" iyz="0.0" izz="0.00000053" />
    </inertial>
    <!-- FOOT LINK COLLISION -->
    <collision>
      <origin rpy="0 0 0" xyz="0 0 0" />
      <geometry>
        <sphere radius="0.02" />
      </geometry>
      <material name="grey">
        <color rgba="0.8 0.8 0.8 1.0" />
      </material>
    </collision>
    <!-- Bullet specific paramters -->
    <contact>
      <lateral_friction value="1.0" />
      <restitution value="0.5" />
    </contact>
  </link>
  <!-- END FOOT LINK -->
</robot>
